<robot name="kuka_iiwa_7">
  <link name="base_link"/>

  <joint name="joint_1" type="revolute">
    <parent link="base_link"/>
    <child link="link_1"/>
    <origin xyz="0 0 0.2" rpy="0 0 0"/>
    <axis xyz="0 0 1"/>
    <limit lower="-3.14" upper="3.14" effort="200" velocity="2.0"/>
  </joint>

  <link name="link_1">
    <inertial>
      <origin xyz="0 0 0.1" rpy="0 0 0"/>
      <mass value="2.0"/>
      <inertia ixx="0.1" iyy="0.1" izz="0.1"/>
    </inertial>
  </link>

  <joint name="joint_2" type="revolute">
    <parent link="link_1"/>
    <child link="link_2"/>
    <origin xyz="0 0 0.4" rpy="0 0 0"/>
    <axis xyz="0 1 0"/>
    <limit lower="-3.14" upper="3.14" effort="200" velocity="2.0"/>
  </joint>

  <link name="link_2">
    <inertial>
      <origin xyz="0 0 0.2" rpy="0 0 0"/>
      <mass value="2.0"/>
      <inertia ixx="0.1" iyy="0.1" izz="0.1"/>
    </inertial>
  </link>

  <!-- Add remaining joints and links following the same pattern -->
  
  <joint name="joint_7" type="revolute">
    <parent link="link_6"/>
    <child link="end_effector"/>
    <origin xyz="0 0 0.2" rpy="0 0 0"/>
    <axis xyz="0 0 1"/>
    <limit lower="-3.14" upper="3.14" effort="200" velocity="2.0"/>
  </joint>

  <link name="end_effector">
    <inertial>
      <origin xyz="0 0 0.05" rpy="0 0 0"/>
      <mass value="0.5"/>
      <inertia ixx="0.01" iyy="0.01" izz="0.01"/>
    </inertial>
  </link>
</robot>
